{
 "cells": [
  {
   "cell_type": "code",
   "execution_count": 1,
   "id": "f15aa38d",
   "metadata": {},
   "outputs": [],
   "source": [
    "# import \n",
    "import tensorflow as tf"
   ]
  },
  {
   "cell_type": "code",
   "execution_count": 4,
   "id": "25b746c3",
   "metadata": {},
   "outputs": [],
   "source": [
    "from keras.preprocessing.image import ImageDataGenerator"
   ]
  },
  {
   "cell_type": "code",
   "execution_count": 9,
   "id": "230d114e",
   "metadata": {},
   "outputs": [
    {
     "name": "stdout",
     "output_type": "stream",
     "text": [
      "Found 8005 images belonging to 2 classes.\n"
     ]
    }
   ],
   "source": [
    "# Data Preprocession\n",
    "train_dataset = ImageDataGenerator(\n",
    "        rescale=1./255,\n",
    "        shear_range=0.2,\n",
    "        zoom_range=0.2,\n",
    "        horizontal_flip=True)\n",
    "\n",
    "train_generator = train_dataset.flow_from_directory(\n",
    "        'dataset/training_set/training_set',\n",
    "        target_size=(64, 64),\n",
    "        batch_size=32,\n",
    "        class_mode='binary')"
   ]
  },
  {
   "cell_type": "code",
   "execution_count": 10,
   "id": "97c6c91f",
   "metadata": {},
   "outputs": [
    {
     "name": "stdout",
     "output_type": "stream",
     "text": [
      "Found 2023 images belonging to 2 classes.\n"
     ]
    }
   ],
   "source": [
    "test_datagen = ImageDataGenerator(rescale=1./255)\n",
    "\n",
    "validation_generator = test_datagen.flow_from_directory(\n",
    "        'dataset/test_set/test_set',\n",
    "        target_size=(150, 150),\n",
    "        batch_size=32,\n",
    "        class_mode='binary')"
   ]
  },
  {
   "cell_type": "code",
   "execution_count": 11,
   "id": "a0278037",
   "metadata": {},
   "outputs": [],
   "source": [
    "# Build CNN Model\n",
    "cnn = tf.keras.models.Sequential() # Initialized"
   ]
  },
  {
   "cell_type": "code",
   "execution_count": 12,
   "id": "ba57e528",
   "metadata": {},
   "outputs": [],
   "source": [
    "# COnvolution\n",
    "cnn.add(tf.keras.layers.Conv2D(filters = 32, kernel_size = 3, activation = 'relu', input_shape = [64,64,3]))"
   ]
  },
  {
   "cell_type": "code",
   "execution_count": 13,
   "id": "ba54ebb6",
   "metadata": {},
   "outputs": [],
   "source": [
    "# Pooling\n",
    "cnn.add(tf.keras.layers.MaxPool2D(pool_size = 2, strides = 2))"
   ]
  },
  {
   "cell_type": "code",
   "execution_count": 14,
   "id": "505480d9",
   "metadata": {},
   "outputs": [],
   "source": [
    "# Add another Layer\n",
    "cnn.add(tf.keras.layers.Conv2D(filters = 32, kernel_size = 3, activation = 'relu'))\n",
    "cnn.add(tf.keras.layers.MaxPool2D(pool_size = 2, strides = 2))"
   ]
  },
  {
   "cell_type": "code",
   "execution_count": 15,
   "id": "71098efb",
   "metadata": {},
   "outputs": [],
   "source": [
    "# Flatten\n",
    "cnn.add(tf.keras.layers.Flatten())"
   ]
  },
  {
   "cell_type": "code",
   "execution_count": 16,
   "id": "66a7a16d",
   "metadata": {},
   "outputs": [],
   "source": [
    "# Full connection\n",
    "cnn.add(tf.keras.layers.Dense(units = 128, activation = 'relu'))"
   ]
  },
  {
   "cell_type": "code",
   "execution_count": 17,
   "id": "8ff02d4d",
   "metadata": {},
   "outputs": [],
   "source": [
    "# Output Layer\n",
    "cnn.add(tf.keras.layers.Dense(units = 1, activation = 'sigmoid'))"
   ]
  },
  {
   "cell_type": "code",
   "execution_count": 18,
   "id": "04257822",
   "metadata": {},
   "outputs": [],
   "source": [
    "# Compile the model\n",
    "cnn.compile(optimizer = 'adam', loss = 'binary_crossentropy', metrics = ['accuracy'])"
   ]
  },
  {
   "cell_type": "code",
   "execution_count": 29,
   "id": "3399fefb",
   "metadata": {},
   "outputs": [
    {
     "name": "stdout",
     "output_type": "stream",
     "text": [
      "Epoch 1/3\n",
      "251/251 [==============================] - ETA: 0s - loss: 0.4550 - accuracy: 0.7801"
     ]
    },
    {
     "ename": "InvalidArgumentError",
     "evalue": "Graph execution error:\n\nDetected at node 'sequential/flatten/Reshape' defined at (most recent call last):\n    File \"C:\\ProgramData\\Anaconda3\\lib\\runpy.py\", line 197, in _run_module_as_main\n      return _run_code(code, main_globals, None,\n    File \"C:\\ProgramData\\Anaconda3\\lib\\runpy.py\", line 87, in _run_code\n      exec(code, run_globals)\n    File \"C:\\ProgramData\\Anaconda3\\lib\\site-packages\\ipykernel_launcher.py\", line 16, in <module>\n      app.launch_new_instance()\n    File \"C:\\ProgramData\\Anaconda3\\lib\\site-packages\\traitlets\\config\\application.py\", line 846, in launch_instance\n      app.start()\n    File \"C:\\ProgramData\\Anaconda3\\lib\\site-packages\\ipykernel\\kernelapp.py\", line 677, in start\n      self.io_loop.start()\n    File \"C:\\ProgramData\\Anaconda3\\lib\\site-packages\\tornado\\platform\\asyncio.py\", line 199, in start\n      self.asyncio_loop.run_forever()\n    File \"C:\\ProgramData\\Anaconda3\\lib\\asyncio\\base_events.py\", line 596, in run_forever\n      self._run_once()\n    File \"C:\\ProgramData\\Anaconda3\\lib\\asyncio\\base_events.py\", line 1890, in _run_once\n      handle._run()\n    File \"C:\\ProgramData\\Anaconda3\\lib\\asyncio\\events.py\", line 80, in _run\n      self._context.run(self._callback, *self._args)\n    File \"C:\\ProgramData\\Anaconda3\\lib\\site-packages\\ipykernel\\kernelbase.py\", line 457, in dispatch_queue\n      await self.process_one()\n    File \"C:\\ProgramData\\Anaconda3\\lib\\site-packages\\ipykernel\\kernelbase.py\", line 446, in process_one\n      await dispatch(*args)\n    File \"C:\\ProgramData\\Anaconda3\\lib\\site-packages\\ipykernel\\kernelbase.py\", line 353, in dispatch_shell\n      await result\n    File \"C:\\ProgramData\\Anaconda3\\lib\\site-packages\\ipykernel\\kernelbase.py\", line 648, in execute_request\n      reply_content = await reply_content\n    File \"C:\\ProgramData\\Anaconda3\\lib\\site-packages\\ipykernel\\ipkernel.py\", line 353, in do_execute\n      res = shell.run_cell(code, store_history=store_history, silent=silent)\n    File \"C:\\ProgramData\\Anaconda3\\lib\\site-packages\\ipykernel\\zmqshell.py\", line 533, in run_cell\n      return super(ZMQInteractiveShell, self).run_cell(*args, **kwargs)\n    File \"C:\\ProgramData\\Anaconda3\\lib\\site-packages\\IPython\\core\\interactiveshell.py\", line 2901, in run_cell\n      result = self._run_cell(\n    File \"C:\\ProgramData\\Anaconda3\\lib\\site-packages\\IPython\\core\\interactiveshell.py\", line 2947, in _run_cell\n      return runner(coro)\n    File \"C:\\ProgramData\\Anaconda3\\lib\\site-packages\\IPython\\core\\async_helpers.py\", line 68, in _pseudo_sync_runner\n      coro.send(None)\n    File \"C:\\ProgramData\\Anaconda3\\lib\\site-packages\\IPython\\core\\interactiveshell.py\", line 3172, in run_cell_async\n      has_raised = await self.run_ast_nodes(code_ast.body, cell_name,\n    File \"C:\\ProgramData\\Anaconda3\\lib\\site-packages\\IPython\\core\\interactiveshell.py\", line 3364, in run_ast_nodes\n      if (await self.run_code(code, result,  async_=asy)):\n    File \"C:\\ProgramData\\Anaconda3\\lib\\site-packages\\IPython\\core\\interactiveshell.py\", line 3444, in run_code\n      exec(code_obj, self.user_global_ns, self.user_ns)\n    File \"C:\\Users\\GameBoy\\AppData\\Local\\Temp/ipykernel_26440/154597525.py\", line 2, in <module>\n      history = cnn.fit(x = train_generator, validation_data = train_generator, epochs = 3)\n    File \"C:\\ProgramData\\Anaconda3\\lib\\site-packages\\keras\\utils\\traceback_utils.py\", line 64, in error_handler\n      return fn(*args, **kwargs)\n    File \"C:\\ProgramData\\Anaconda3\\lib\\site-packages\\keras\\engine\\training.py\", line 1420, in fit\n      val_logs = self.evaluate(\n    File \"C:\\ProgramData\\Anaconda3\\lib\\site-packages\\keras\\utils\\traceback_utils.py\", line 64, in error_handler\n      return fn(*args, **kwargs)\n    File \"C:\\ProgramData\\Anaconda3\\lib\\site-packages\\keras\\engine\\training.py\", line 1716, in evaluate\n      tmp_logs = self.test_function(iterator)\n    File \"C:\\ProgramData\\Anaconda3\\lib\\site-packages\\keras\\engine\\training.py\", line 1525, in test_function\n      return step_function(self, iterator)\n    File \"C:\\ProgramData\\Anaconda3\\lib\\site-packages\\keras\\engine\\training.py\", line 1514, in step_function\n      outputs = model.distribute_strategy.run(run_step, args=(data,))\n    File \"C:\\ProgramData\\Anaconda3\\lib\\site-packages\\keras\\engine\\training.py\", line 1507, in run_step\n      outputs = model.test_step(data)\n    File \"C:\\ProgramData\\Anaconda3\\lib\\site-packages\\keras\\engine\\training.py\", line 1471, in test_step\n      y_pred = self(x, training=False)\n    File \"C:\\ProgramData\\Anaconda3\\lib\\site-packages\\keras\\utils\\traceback_utils.py\", line 64, in error_handler\n      return fn(*args, **kwargs)\n    File \"C:\\ProgramData\\Anaconda3\\lib\\site-packages\\keras\\engine\\base_layer.py\", line 1096, in __call__\n      outputs = call_fn(inputs, *args, **kwargs)\n    File \"C:\\ProgramData\\Anaconda3\\lib\\site-packages\\keras\\utils\\traceback_utils.py\", line 92, in error_handler\n      return fn(*args, **kwargs)\n    File \"C:\\ProgramData\\Anaconda3\\lib\\site-packages\\keras\\engine\\sequential.py\", line 374, in call\n      return super(Sequential, self).call(inputs, training=training, mask=mask)\n    File \"C:\\ProgramData\\Anaconda3\\lib\\site-packages\\keras\\engine\\functional.py\", line 451, in call\n      return self._run_internal_graph(\n    File \"C:\\ProgramData\\Anaconda3\\lib\\site-packages\\keras\\engine\\functional.py\", line 589, in _run_internal_graph\n      outputs = node.layer(*args, **kwargs)\n    File \"C:\\ProgramData\\Anaconda3\\lib\\site-packages\\keras\\utils\\traceback_utils.py\", line 64, in error_handler\n      return fn(*args, **kwargs)\n    File \"C:\\ProgramData\\Anaconda3\\lib\\site-packages\\keras\\engine\\base_layer.py\", line 1096, in __call__\n      outputs = call_fn(inputs, *args, **kwargs)\n    File \"C:\\ProgramData\\Anaconda3\\lib\\site-packages\\keras\\utils\\traceback_utils.py\", line 92, in error_handler\n      return fn(*args, **kwargs)\n    File \"C:\\ProgramData\\Anaconda3\\lib\\site-packages\\keras\\layers\\core\\flatten.py\", line 96, in call\n      return tf.reshape(inputs, flattened_shape)\nNode: 'sequential/flatten/Reshape'\nInput to reshape is a tensor with 1327104 values, but the requested shape requires a multiple of 6272\n\t [[{{node sequential/flatten/Reshape}}]] [Op:__inference_test_function_2037]",
     "output_type": "error",
     "traceback": [
      "\u001b[1;31m---------------------------------------------------------------------------\u001b[0m",
      "\u001b[1;31mInvalidArgumentError\u001b[0m                      Traceback (most recent call last)",
      "\u001b[1;32m~\\AppData\\Local\\Temp/ipykernel_26440/1792445769.py\u001b[0m in \u001b[0;36m<module>\u001b[1;34m\u001b[0m\n\u001b[0;32m      1\u001b[0m \u001b[1;31m# train the model\u001b[0m\u001b[1;33m\u001b[0m\u001b[1;33m\u001b[0m\u001b[0m\n\u001b[1;32m----> 2\u001b[1;33m \u001b[0mhistory\u001b[0m \u001b[1;33m=\u001b[0m \u001b[0mcnn\u001b[0m\u001b[1;33m.\u001b[0m\u001b[0mfit\u001b[0m\u001b[1;33m(\u001b[0m\u001b[0mx\u001b[0m \u001b[1;33m=\u001b[0m \u001b[0mtrain_generator\u001b[0m\u001b[1;33m,\u001b[0m \u001b[0mvalidation_data\u001b[0m \u001b[1;33m=\u001b[0m \u001b[0mvalidation_generator\u001b[0m\u001b[1;33m,\u001b[0m \u001b[0mepochs\u001b[0m \u001b[1;33m=\u001b[0m \u001b[1;36m3\u001b[0m\u001b[1;33m)\u001b[0m\u001b[1;33m\u001b[0m\u001b[1;33m\u001b[0m\u001b[0m\n\u001b[0m",
      "\u001b[1;32mC:\\ProgramData\\Anaconda3\\lib\\site-packages\\keras\\utils\\traceback_utils.py\u001b[0m in \u001b[0;36merror_handler\u001b[1;34m(*args, **kwargs)\u001b[0m\n\u001b[0;32m     65\u001b[0m     \u001b[1;32mexcept\u001b[0m \u001b[0mException\u001b[0m \u001b[1;32mas\u001b[0m \u001b[0me\u001b[0m\u001b[1;33m:\u001b[0m  \u001b[1;31m# pylint: disable=broad-except\u001b[0m\u001b[1;33m\u001b[0m\u001b[1;33m\u001b[0m\u001b[0m\n\u001b[0;32m     66\u001b[0m       \u001b[0mfiltered_tb\u001b[0m \u001b[1;33m=\u001b[0m \u001b[0m_process_traceback_frames\u001b[0m\u001b[1;33m(\u001b[0m\u001b[0me\u001b[0m\u001b[1;33m.\u001b[0m\u001b[0m__traceback__\u001b[0m\u001b[1;33m)\u001b[0m\u001b[1;33m\u001b[0m\u001b[1;33m\u001b[0m\u001b[0m\n\u001b[1;32m---> 67\u001b[1;33m       \u001b[1;32mraise\u001b[0m \u001b[0me\u001b[0m\u001b[1;33m.\u001b[0m\u001b[0mwith_traceback\u001b[0m\u001b[1;33m(\u001b[0m\u001b[0mfiltered_tb\u001b[0m\u001b[1;33m)\u001b[0m \u001b[1;32mfrom\u001b[0m \u001b[1;32mNone\u001b[0m\u001b[1;33m\u001b[0m\u001b[1;33m\u001b[0m\u001b[0m\n\u001b[0m\u001b[0;32m     68\u001b[0m     \u001b[1;32mfinally\u001b[0m\u001b[1;33m:\u001b[0m\u001b[1;33m\u001b[0m\u001b[1;33m\u001b[0m\u001b[0m\n\u001b[0;32m     69\u001b[0m       \u001b[1;32mdel\u001b[0m \u001b[0mfiltered_tb\u001b[0m\u001b[1;33m\u001b[0m\u001b[1;33m\u001b[0m\u001b[0m\n",
      "\u001b[1;32mC:\\ProgramData\\Anaconda3\\lib\\site-packages\\tensorflow\\python\\eager\\execute.py\u001b[0m in \u001b[0;36mquick_execute\u001b[1;34m(op_name, num_outputs, inputs, attrs, ctx, name)\u001b[0m\n\u001b[0;32m     52\u001b[0m   \u001b[1;32mtry\u001b[0m\u001b[1;33m:\u001b[0m\u001b[1;33m\u001b[0m\u001b[1;33m\u001b[0m\u001b[0m\n\u001b[0;32m     53\u001b[0m     \u001b[0mctx\u001b[0m\u001b[1;33m.\u001b[0m\u001b[0mensure_initialized\u001b[0m\u001b[1;33m(\u001b[0m\u001b[1;33m)\u001b[0m\u001b[1;33m\u001b[0m\u001b[1;33m\u001b[0m\u001b[0m\n\u001b[1;32m---> 54\u001b[1;33m     tensors = pywrap_tfe.TFE_Py_Execute(ctx._handle, device_name, op_name,\n\u001b[0m\u001b[0;32m     55\u001b[0m                                         inputs, attrs, num_outputs)\n\u001b[0;32m     56\u001b[0m   \u001b[1;32mexcept\u001b[0m \u001b[0mcore\u001b[0m\u001b[1;33m.\u001b[0m\u001b[0m_NotOkStatusException\u001b[0m \u001b[1;32mas\u001b[0m \u001b[0me\u001b[0m\u001b[1;33m:\u001b[0m\u001b[1;33m\u001b[0m\u001b[1;33m\u001b[0m\u001b[0m\n",
      "\u001b[1;31mInvalidArgumentError\u001b[0m: Graph execution error:\n\nDetected at node 'sequential/flatten/Reshape' defined at (most recent call last):\n    File \"C:\\ProgramData\\Anaconda3\\lib\\runpy.py\", line 197, in _run_module_as_main\n      return _run_code(code, main_globals, None,\n    File \"C:\\ProgramData\\Anaconda3\\lib\\runpy.py\", line 87, in _run_code\n      exec(code, run_globals)\n    File \"C:\\ProgramData\\Anaconda3\\lib\\site-packages\\ipykernel_launcher.py\", line 16, in <module>\n      app.launch_new_instance()\n    File \"C:\\ProgramData\\Anaconda3\\lib\\site-packages\\traitlets\\config\\application.py\", line 846, in launch_instance\n      app.start()\n    File \"C:\\ProgramData\\Anaconda3\\lib\\site-packages\\ipykernel\\kernelapp.py\", line 677, in start\n      self.io_loop.start()\n    File \"C:\\ProgramData\\Anaconda3\\lib\\site-packages\\tornado\\platform\\asyncio.py\", line 199, in start\n      self.asyncio_loop.run_forever()\n    File \"C:\\ProgramData\\Anaconda3\\lib\\asyncio\\base_events.py\", line 596, in run_forever\n      self._run_once()\n    File \"C:\\ProgramData\\Anaconda3\\lib\\asyncio\\base_events.py\", line 1890, in _run_once\n      handle._run()\n    File \"C:\\ProgramData\\Anaconda3\\lib\\asyncio\\events.py\", line 80, in _run\n      self._context.run(self._callback, *self._args)\n    File \"C:\\ProgramData\\Anaconda3\\lib\\site-packages\\ipykernel\\kernelbase.py\", line 457, in dispatch_queue\n      await self.process_one()\n    File \"C:\\ProgramData\\Anaconda3\\lib\\site-packages\\ipykernel\\kernelbase.py\", line 446, in process_one\n      await dispatch(*args)\n    File \"C:\\ProgramData\\Anaconda3\\lib\\site-packages\\ipykernel\\kernelbase.py\", line 353, in dispatch_shell\n      await result\n    File \"C:\\ProgramData\\Anaconda3\\lib\\site-packages\\ipykernel\\kernelbase.py\", line 648, in execute_request\n      reply_content = await reply_content\n    File \"C:\\ProgramData\\Anaconda3\\lib\\site-packages\\ipykernel\\ipkernel.py\", line 353, in do_execute\n      res = shell.run_cell(code, store_history=store_history, silent=silent)\n    File \"C:\\ProgramData\\Anaconda3\\lib\\site-packages\\ipykernel\\zmqshell.py\", line 533, in run_cell\n      return super(ZMQInteractiveShell, self).run_cell(*args, **kwargs)\n    File \"C:\\ProgramData\\Anaconda3\\lib\\site-packages\\IPython\\core\\interactiveshell.py\", line 2901, in run_cell\n      result = self._run_cell(\n    File \"C:\\ProgramData\\Anaconda3\\lib\\site-packages\\IPython\\core\\interactiveshell.py\", line 2947, in _run_cell\n      return runner(coro)\n    File \"C:\\ProgramData\\Anaconda3\\lib\\site-packages\\IPython\\core\\async_helpers.py\", line 68, in _pseudo_sync_runner\n      coro.send(None)\n    File \"C:\\ProgramData\\Anaconda3\\lib\\site-packages\\IPython\\core\\interactiveshell.py\", line 3172, in run_cell_async\n      has_raised = await self.run_ast_nodes(code_ast.body, cell_name,\n    File \"C:\\ProgramData\\Anaconda3\\lib\\site-packages\\IPython\\core\\interactiveshell.py\", line 3364, in run_ast_nodes\n      if (await self.run_code(code, result,  async_=asy)):\n    File \"C:\\ProgramData\\Anaconda3\\lib\\site-packages\\IPython\\core\\interactiveshell.py\", line 3444, in run_code\n      exec(code_obj, self.user_global_ns, self.user_ns)\n    File \"C:\\Users\\GameBoy\\AppData\\Local\\Temp/ipykernel_26440/154597525.py\", line 2, in <module>\n      history = cnn.fit(x = train_generator, validation_data = train_generator, epochs = 3)\n    File \"C:\\ProgramData\\Anaconda3\\lib\\site-packages\\keras\\utils\\traceback_utils.py\", line 64, in error_handler\n      return fn(*args, **kwargs)\n    File \"C:\\ProgramData\\Anaconda3\\lib\\site-packages\\keras\\engine\\training.py\", line 1420, in fit\n      val_logs = self.evaluate(\n    File \"C:\\ProgramData\\Anaconda3\\lib\\site-packages\\keras\\utils\\traceback_utils.py\", line 64, in error_handler\n      return fn(*args, **kwargs)\n    File \"C:\\ProgramData\\Anaconda3\\lib\\site-packages\\keras\\engine\\training.py\", line 1716, in evaluate\n      tmp_logs = self.test_function(iterator)\n    File \"C:\\ProgramData\\Anaconda3\\lib\\site-packages\\keras\\engine\\training.py\", line 1525, in test_function\n      return step_function(self, iterator)\n    File \"C:\\ProgramData\\Anaconda3\\lib\\site-packages\\keras\\engine\\training.py\", line 1514, in step_function\n      outputs = model.distribute_strategy.run(run_step, args=(data,))\n    File \"C:\\ProgramData\\Anaconda3\\lib\\site-packages\\keras\\engine\\training.py\", line 1507, in run_step\n      outputs = model.test_step(data)\n    File \"C:\\ProgramData\\Anaconda3\\lib\\site-packages\\keras\\engine\\training.py\", line 1471, in test_step\n      y_pred = self(x, training=False)\n    File \"C:\\ProgramData\\Anaconda3\\lib\\site-packages\\keras\\utils\\traceback_utils.py\", line 64, in error_handler\n      return fn(*args, **kwargs)\n    File \"C:\\ProgramData\\Anaconda3\\lib\\site-packages\\keras\\engine\\base_layer.py\", line 1096, in __call__\n      outputs = call_fn(inputs, *args, **kwargs)\n    File \"C:\\ProgramData\\Anaconda3\\lib\\site-packages\\keras\\utils\\traceback_utils.py\", line 92, in error_handler\n      return fn(*args, **kwargs)\n    File \"C:\\ProgramData\\Anaconda3\\lib\\site-packages\\keras\\engine\\sequential.py\", line 374, in call\n      return super(Sequential, self).call(inputs, training=training, mask=mask)\n    File \"C:\\ProgramData\\Anaconda3\\lib\\site-packages\\keras\\engine\\functional.py\", line 451, in call\n      return self._run_internal_graph(\n    File \"C:\\ProgramData\\Anaconda3\\lib\\site-packages\\keras\\engine\\functional.py\", line 589, in _run_internal_graph\n      outputs = node.layer(*args, **kwargs)\n    File \"C:\\ProgramData\\Anaconda3\\lib\\site-packages\\keras\\utils\\traceback_utils.py\", line 64, in error_handler\n      return fn(*args, **kwargs)\n    File \"C:\\ProgramData\\Anaconda3\\lib\\site-packages\\keras\\engine\\base_layer.py\", line 1096, in __call__\n      outputs = call_fn(inputs, *args, **kwargs)\n    File \"C:\\ProgramData\\Anaconda3\\lib\\site-packages\\keras\\utils\\traceback_utils.py\", line 92, in error_handler\n      return fn(*args, **kwargs)\n    File \"C:\\ProgramData\\Anaconda3\\lib\\site-packages\\keras\\layers\\core\\flatten.py\", line 96, in call\n      return tf.reshape(inputs, flattened_shape)\nNode: 'sequential/flatten/Reshape'\nInput to reshape is a tensor with 1327104 values, but the requested shape requires a multiple of 6272\n\t [[{{node sequential/flatten/Reshape}}]] [Op:__inference_test_function_2037]"
     ]
    }
   ],
   "source": [
    "# train the model\n",
    "history = cnn.fit(x = train_generator, validation_data = validation_generator, epochs = 3)"
   ]
  },
  {
   "cell_type": "code",
   "execution_count": 24,
   "id": "05709d6a",
   "metadata": {},
   "outputs": [
    {
     "name": "stdout",
     "output_type": "stream",
     "text": [
      "dog\n"
     ]
    }
   ],
   "source": [
    "# Make prediction\n",
    "import numpy as np\n",
    "from keras.preprocessing import image\n",
    "test_image = image.load_img(\"dataset/prediction/predict_2.jpg\", target_size = (64,64))\n",
    "test_image = image.img_to_array(test_image)\n",
    "test_image = np.expand_dims(test_image, axis = 0)\n",
    "result = cnn.predict(test_image)\n",
    "if result[0][0] == 1:\n",
    "    prediction = 'dog'\n",
    "else:\n",
    "    prediction = 'cat'\n",
    "\n",
    "print(prediction)"
   ]
  },
  {
   "cell_type": "code",
   "execution_count": null,
   "id": "a6a4057d",
   "metadata": {},
   "outputs": [],
   "source": [
    "import matplotlib.pyplot as plt\n",
    "print(history.history.keys())\n",
    "# loss, accuracy, val_loss, val_accuracy"
   ]
  },
  {
   "cell_type": "code",
   "execution_count": null,
   "id": "f3630a66",
   "metadata": {},
   "outputs": [],
   "source": [
    "plt.plot(histpry.history['accuracy'])"
   ]
  }
 ],
 "metadata": {
  "kernelspec": {
   "display_name": "Python 3 (ipykernel)",
   "language": "python",
   "name": "python3"
  },
  "language_info": {
   "codemirror_mode": {
    "name": "ipython",
    "version": 3
   },
   "file_extension": ".py",
   "mimetype": "text/x-python",
   "name": "python",
   "nbconvert_exporter": "python",
   "pygments_lexer": "ipython3",
   "version": "3.9.7"
  }
 },
 "nbformat": 4,
 "nbformat_minor": 5
}
